<?xml version="1.0"?>
<robot name="robot_arm">

<!-- world link -->
<link name="world"/>

<!-- base of the robot arm and its fixed joint to the floor -->
<joint name="joint_fix" type="fixed">
  <parent link="world"/>
  <child link="base"/>
</joint>

<link name="base">

  <visual>
    <origin xyz="0 0 0.05" rpy="0 0 0"/>
    <geometry>
      <box size="0.5 0.5 0.1"/>
    </geometry>
  </visual>

  <inertial>
    <origin xyz="0 0 0.1" rpy="0 0 0"/>
    <mass value="1"/>
    <inertia
      ixx="1.0" ixy="0.0" ixz="0.0"
      iyy="1.0" iyz="0.0"
      izz="1.0"/>
  </inertial>

</link>

<gazebo reference="base">
  <mu1>0</mu1>
  <mu2>0</mu2>
  <material>Gazebo/FlatBlack</material>
</gazebo>

<!-- Torso of the robot arm and its fixed joint to the base -->
<joint name="joint_fix0" type="fixed">
  <parent link="base"/>
  <child link="torso"/>
</joint>

<link name="torso">

  <visual>
    <origin xyz="0 0 0.35" rpy="0 0 0"/>
    <geometry>
      <cylinder length="0.5" radius="0.1"/>
    </geometry>
  </visual>

  <inertial>
    <origin xyz="0 0 0.35" rpy="0 0 0"/>
    <mass value="1"/>
    <inertia
      ixx="1.0" ixy="0.0" ixz="0.0"
      iyy="1.0" iyz="0.0"
      izz="1.0"/>
  </inertial>

</link>

<gazebo reference="torso">
  <mu1>0</mu1>
  <mu2>0</mu2>
  <material>Gazebo/FlatBlack</material>
</gazebo>


<!-- the first arm of the scara, with revolute joint rotating along z axis -->
<!-- arm length between two rotation axis is 1 -->
<joint name="rotation1" type="revolute">
  <parent link="torso"/>
  <child link="arm1"/>
  <origin xyz="0 0 0.4" rpy="0.6 0 0"/>
  <axis xyz="0 0 1"/>
  <limit effort="100" velocity="100" lower="-2.6" upper="2.6"/>
</joint>

<link name="arm1">
  <collision>
    <origin xyz="0 0.5 0.05" rpy="0 0 0"/>
    <geometry>
      <box size="0.1 1.1 0.1"/>
    </geometry>
  </collision>

  <visual>
    <origin xyz="0 0.5 0.05" rpy="0 0 0"/>
    <geometry>
      <box size="0.1 2.1 0.1"/>
    </geometry>
  </visual>

  <inertial>
    <origin xyz="0 0 0.05" rpy="0 0 0"/>
    <mass value="1"/>
    <inertia
      ixx="0.001" ixy="0.0" ixz="0.0"
      iyy="0.001" iyz="0.0"
      izz="0.001"/>
  </inertial>
</link>

<gazebo reference="arm1">
  <material>Gazebo/Grey</material>
</gazebo>


<!-- the second arm and its rotation joint -->
<!-- arm length between two rotation axis is 0.8 -->
<joint name="rotation2" type="revolute">
  <parent link="arm1"/>
  <child link="arm2"/>
  <origin xyz="0 1 0.1" rpy="-0.8 0 0"/>
  <axis xyz="0 0 1"/>
  <limit effort="100" velocity="100" lower="-3.00" upper="3.00"/>
  <!-- if set to -pi to pi, robot will self collide -->
</joint>

<link name="arm2">
  <collision>
    <origin xyz="0 0.4 0.05" rpy="0 0 0"/>
    <geometry>
      <box size="0.1 0.9 0.1"/>
    </geometry>
  </collision>

  <visual>
    <origin xyz="0 0.4 0.05" rpy="0 0 0"/>
    <geometry>
      <box size="0.1 0.9 0.1"/>
    </geometry>
  </visual>

  <inertial>
    <origin xyz="0 0 0.05" rpy="0 0 0"/>
    <mass value="1"/>
    <inertia
      ixx="0.001" ixy="0.0" ixz="0.0"
      iyy="0.001" iyz="0.0"
      izz="0.001"/>
  </inertial>
</link>

<gazebo reference="arm2">
  <material>Gazebo/Grey</material>
</gazebo>


</robot>

